#VRML_SIM R2023b utf8

EXTERNPROTO "https://raw.githubusercontent.com/cyberbotics/webots/R2023b/projects/objects/backgrounds/protos/TexturedBackground.proto"
EXTERNPROTO "https://raw.githubusercontent.com/cyberbotics/webots/R2023b/projects/objects/backgrounds/protos/TexturedBackgroundLight.proto"
EXTERNPROTO "https://raw.githubusercontent.com/cyberbotics/webots/R2023b/projects/objects/floors/protos/RectangleArena.proto"

WorldInfo {
  basicTimeStep 8
}
Viewpoint {
  orientation -0.20836726170734407 -0.5247011338795922 0.8253919095520948 5.3863405711913295
  position -0.4674388844971667 0.44640912158661367 0.4043741433130227
}
TexturedBackground {
}
TexturedBackgroundLight {
}
PointLight {
  attenuation 0 0 1
  location -0.5 0 0.3
  on FALSE
}
RectangleArena {
}
Solid {
  translation 0.312432 0.295028 0.1
  children [
    Shape {
      appearance PBRAppearance {
        baseColor 0.0588235 1 0.654902
        roughness 0.5
        metalness 0.5
      }
      geometry DEF BOX1 Box {
        size 0.2 0.2 0.2
      }
    }
  ]
  boundingObject USE BOX1
  physics Physics {
    density -1
    mass 0.1
  }
}
Robot {
  translation 0 0 0.06
  children [
    DEF BODY Shape {
      appearance PBRAppearance {
        transparency 0.5
      }
      geometry Box {
        size 0.2 0.1 0.05
      }
    }
    HingeJoint {
      jointParameters HingeJointParameters {
        axis 0 1 0
        anchor 0.05 0.06 0
      }
      device [
        RotationalMotor {
          name "wheel1"
        }
      ]
      endPoint DEF WHEEL1 Solid {
        translation 0.05 0.06 0
        rotation 1 0 0 1.5708
        children [
          Shape {
            geometry Cylinder {
              height 0.02
              radius 0.04
            }
          }
        ]
      }
    }
  ]
  boundingObject USE BODY
  physics Physics {
  }
}
