#VRML_SIM R2023b utf8

EXTERNPROTO "https://raw.githubusercontent.com/cyberbotics/webots/R2023b/projects/objects/backgrounds/protos/TexturedBackground.proto"
EXTERNPROTO "https://raw.githubusercontent.com/cyberbotics/webots/R2023b/projects/objects/backgrounds/protos/TexturedBackgroundLight.proto"
EXTERNPROTO "https://raw.githubusercontent.com/cyberbotics/webots/R2023b/projects/objects/floors/protos/RectangleArena.proto"

WorldInfo {
  basicTimeStep 8
}
Viewpoint {
  orientation 0.3834755463867937 -0.3528361330401589 -0.8534946798572428 4.473008155981543
  position 0.07369587229413103 -0.5136244428309285 0.6715773773735659
}
TexturedBackground {
}
TexturedBackgroundLight {
}
PointLight {
  attenuation 0 0 1
  location -0.5 0 0.3
  on FALSE
}
RectangleArena {
}
Solid {
  translation 0.312432 0.295028 0.1
  children [
    Shape {
      appearance PBRAppearance {
        baseColor 0.0588235 1 0.654902
        roughness 0.5
        metalness 0.5
      }
      geometry DEF BOX1 Box {
        size 0.2 0.2 0.2
      }
    }
  ]
  boundingObject USE BOX1
  physics Physics {
    density -1
    mass 0.1
  }
}
Robot {
  translation 0 0 0.06
  children [
    DistanceSensor {
      translation 0.105087 0.0325072 0
      rotation 0 0 1 0.3
      children [
        Shape {
          geometry Box {
            size 0.01 0.01 0.01
          }
        }
      ]
    }
    DistanceSensor {
      translation 0.105087 -0.0325072 0
      rotation 0 0 1 -0.3
      children [
        Shape {
          geometry Box {
            size 0.01 0.01 0.01
          }
        }
      ]
      name "distance sensor(1)"
    }
    DEF BODY Shape {
      appearance PBRAppearance {
        transparency 0.5
      }
      geometry Box {
        size 0.2 0.1 0.05
      }
    }
    HingeJoint {
      jointParameters HingeJointParameters {
        axis 0 1 0
        anchor 0.05 0.06 0
      }
      device [
        RotationalMotor {
          name "wheel1"
        }
      ]
      endPoint DEF WHEEL1 Solid {
        translation 0.05 0.06 0
        rotation 1 0 0 1.5708
        children [
          DEF WHEEL Shape {
            appearance PBRAppearance {
              baseColor 0.447059 0.85098 0.513726
              roughness 0.5
            }
            geometry Cylinder {
              height 0.02
              radius 0.04
            }
          }
        ]
        boundingObject USE WHEEL
        physics DEF WHEEL_PH Physics {
        }
      }
    }
    HingeJoint {
      jointParameters HingeJointParameters {
        axis 0 1 0
        anchor 0.05 -0.06 0
      }
      device [
        RotationalMotor {
          name "wheel2"
        }
      ]
      endPoint DEF WHEEL2 Solid {
        translation 0.05 -0.06 0
        rotation 1 0 0 1.5708
        children [
          DEF WHEEL Shape {
            appearance PBRAppearance {
              baseColor 0.447059 0.85098 0.513726
              roughness 0.5
            }
            geometry Cylinder {
              height 0.02
              radius 0.04
            }
          }
        ]
        name "solid(1)"
        boundingObject USE WHEEL
        physics DEF WHEEL_PH Physics {
        }
      }
    }
    HingeJoint {
      jointParameters HingeJointParameters {
        axis 0 1 0
        anchor -0.05 0.06 0
      }
      device [
        RotationalMotor {
          name "wheel3"
        }
      ]
      endPoint DEF WHEEL3 Solid {
        translation -0.05 0.06 0
        rotation 1 0 0 1.5708
        children [
          DEF WHEEL Shape {
            appearance PBRAppearance {
              baseColor 0.447059 0.85098 0.513726
              roughness 0.5
            }
            geometry Cylinder {
              height 0.02
              radius 0.04
            }
          }
        ]
        name "solid(2)"
        boundingObject USE WHEEL
        physics DEF WHEEL_PH Physics {
        }
      }
    }
    HingeJoint {
      jointParameters HingeJointParameters {
        axis 0 1 0
        anchor -0.05 -0.06 0
      }
      device [
        RotationalMotor {
          name "wheel4"
        }
      ]
      endPoint DEF WHEEL4 Solid {
        translation -0.05 -0.06 0
        rotation 1 0 0 1.5708
        children [
          DEF WHEEL Shape {
            appearance PBRAppearance {
              baseColor 0.447059 0.85098 0.513726
              roughness 0.5
            }
            geometry Cylinder {
              height 0.02
              radius 0.04
            }
          }
        ]
        name "solid(3)"
        boundingObject USE WHEEL
        physics DEF WHEEL_PH Physics {
        }
      }
    }
  ]
  boundingObject USE BODY
  physics Physics {
  }
}
