#VRML_SIM R2023b utf8

EXTERNPROTO "https://raw.githubusercontent.com/cyberbotics/webots/R2023b/projects/objects/backgrounds/protos/TexturedBackground.proto"
EXTERNPROTO "https://raw.githubusercontent.com/cyberbotics/webots/R2023b/projects/objects/backgrounds/protos/TexturedBackgroundLight.proto"
EXTERNPROTO "https://raw.githubusercontent.com/cyberbotics/webots/R2023b/projects/objects/floors/protos/RectangleArena.proto"

WorldInfo {
  basicTimeStep 8
}
Viewpoint {
  orientation -0.34037237447026064 -0.5703931916306715 0.7475280955515002 4.935822441539511
  position -0.9984192712254842 1.9451254478791689 2.577358693493094
}
TexturedBackground {
}
TexturedBackgroundLight {
}
PointLight {
  attenuation 0 0 1
  location -0.5 0 0.3
  on FALSE
}
RectangleArena {
}
Solid {
  translation 0.259229 0.194575 0.1
  children [
    Shape {
      appearance PBRAppearance {
        baseColor 0.0588235 1 0.654902
        roughness 0.5
        metalness 0.5
      }
      geometry DEF BOX1 Box {
        size 0.2 0.2 0.2
      }
    }
  ]
  boundingObject USE BOX1
  physics Physics {
    density -1
    mass 0.1
  }
}
Robot {
  children [
    HingeJoint {
      endPoint DEF WHEEL1 Solid {
      }
    }
    HingeJoint {
      endPoint DEF WHEEL2 Solid {
        name "solid(1)"
      }
    }
    HingeJoint {
      endPoint DEF WHEEL3 Solid {
        name "solid(2)"
      }
    }
    HingeJoint {
      endPoint DEF WHEEL4 Solid {
        name "solid(3)"
      }
    }
  ]
}
